Workbook

Sheet Assumptions
A1: The Coca-Cola Company (KO) — Assumptions
A3: Scenario | B3: Base | C3: Bear | D3: Base | E3: Bull
A4: Assumption | B4: Active | C4: Bear | D4: Base | E4: Bull
A5: INCOME STATEMENT
A6: Revenue Growth 2026F | B6: =IF($B$3="Bear",C6,IF($B$3="Base",D6,E6)) -> 0.05 | C6: 0.04 | D6: 0.05 | E6: 0.06
A7: Revenue Growth 2027F | B7: =IF($B$3="Bear",C7,IF($B$3="Base",D7,E7)) -> 0.05 | C7: 0.04 | D7: 0.05 | E7: 0.06
A8: Gross Margin % | B8: =IF($B$3="Bear",C8,IF($B$3="Base",D8,E8)) -> 0.615 | C8: 0.6 | D8: 0.615 | E8: 0.625
A9: SG&A % of Revenue | B9: =IF($B$3="Bear",C9,IF($B$3="Base",D9,E9)) -> 0.305 | C9: 0.315 | D9: 0.305 | E9: 0.295
A10: Effective Tax Rate | B10: =IF($B$3="Bear",C10,IF($B$3="Base",D10,E10)) -> 0.185 | C10: 0.2 | D10: 0.185 | E10: 0.175
A11: Dividend Payout Ratio | B11: =IF($B$3="Bear",C11,IF($B$3="Base",D11,E11)) -> 0.75 | C11: 0.8 | D11: 0.75 | E11: 0.7
A12: PP&E SCHEDULE
A13: CapEx % of Revenue | B13: =IF($B$3="Bear",C13,IF($B$3="Base",D13,E13)) -> 0.044 | C13: 0.047 | D13: 0.044 | E13: 0.04
A14: Depreciation Rate | B14: =IF($B$3="Bear",C14,IF($B$3="Base",D14,E14)) -> 0.11 | C14: 0.11 | D14: 0.11 | E14: 0.11
A15: WORKING CAPITAL
A16: DSO (days) | B16: =IF($B$3="Bear",C16,IF($B$3="Base",D16,E16)) -> 35 | C16: 38 | D16: 35 | E16: 32
A17: DIO (days) | B17: =IF($B$3="Bear",C17,IF($B$3="Base",D17,E17)) -> 37 | C17: 40 | D17: 37 | E17: 34
A18: DPO (days) | B18: =IF($B$3="Bear",C18,IF($B$3="Base",D18,E18)) -> 300 | C18: 290 | D18: 300 | E18: 315
A19: DEBT SCHEDULE
A20: Annual Debt Repayment ($m) | B20: =IF($B$3="Bear",C20,IF($B$3="Base",D20,E20)) -> 5000 | C20: 4000 | D20: 5000 | E20: 6000
A21: Interest Rate on Debt | B21: =IF($B$3="Bear",C21,IF($B$3="Base",D21,E21)) -> 0.036 | C21: 0.038 | D21: 0.036 | E21: 0.034
A22: Blue = editable | Black = formula | USD millions | Select scenario in B3

Sheet Model
A1: The Coca-Cola Company (KO) — Integrated 3-Statement Model ($ millions)
A2: Blue = hardcoded input | Black = formula | Forecast driven by Assumptions tab | Fiscal year end: December 31 | Currency: USD
C3: 2022A | D3: 2023A | E3: 2024A | F3: 2025A | G3: 2026F | H3: 2027F
A4: INCOME STATEMENT
A6: Revenue | C6: 43004 | D6: 45754 | E6: 47061 | F6: 47941 | G6: =F6*(1+Assumptions!B6) -> 50338.05 | H6: =G6*(1+Assumptions!B7) -> 52854.952
A8: Cost of Goods Sold (COGS) | C8: -18000 | D8: -18520 | E8: -18324 | F8: -18397 | G8: =-(G6*(1-Assumptions!B8)) -> -19380.149 | H8: =-(H6*(1-Assumptions!B8)) -> -20349.157
A10: Gross Profit | C10: =C6+C8 -> 25004 | D10: =D6+D8 -> 27234 | E10: =E6+E8 -> 28737 | F10: =F6+F8 -> 29544 | G10: =G6+G8 -> 30957.901 | H10: =H6+H8 -> 32505.796
A11: Gross Margin % | C11: =C10/C6 -> 0.58143429 | D11: =D10/D6 -> 0.59522665 | E11: =E10/E6 -> 0.61063301 | F11: =F10/F6 -> 0.61625748 | G11: =G10/G6 -> 0.615 | H11: =H10/H6 -> 0.615
A13: Operating Expenses
A15: Selling, General & Administrative (SG&A) | C15: -12880 | D15: -13972 | E15: -14582 | F15: -14521 | G15: =-(G6*Assumptions!B9) -> -15353.105 | H15: =-(H6*Assumptions!B9) -> -16120.761
A16: Research & Development | C16: 0 | D16: 0 | E16: 0 | F16: 0 | G16: 0 | H16: 0
A17: Other Operating Income / (Expense) | C17: -1215 | D17: -1951 | E17: -4163 | F17: -1261 | G17: 0 | H17: 0
A18: Total Operating Expenses | C18: =C15+C16+C17 -> -14095 | D18: =D15+D16+D17 -> -15923 | E18: =E15+E16+E17 -> -18745 | F18: =F15+F16+F17 -> -15782 | G18: =G15+G16+G17 -> -15353.105 | H18: =H15+H16+H17 -> -16120.761
A20: EBITDA | C20: =C10+C18 -> 10909 | D20: =D10+D18 -> 11311 | E20: =E10+E18 -> 9992 | F20: =F10+F18 -> 13762 | G20: =G10+G18 -> 15604.796 | H20: =H10+H18 -> 16385.035
A21: EBITDA Margin % | C21: =C20/C6 -> 0.25367408 | D21: =D20/D6 -> 0.24721336 | E21: =E20/E6 -> 0.21232018 | F21: =F20/F6 -> 0.28706118 | G21: =G20/G6 -> 0.31 | H21: =H20/H6 -> 0.31
A23: Depreciation & Amortisation (from PP&E Schedule) | C23: =C55 -> -1260 | D23: =D55 -> -1128 | E23: =E55 -> -1075 | F23: =F55 -> -1050 | G23: =G55 -> -1057.43 | H23: =H55 -> -1184.7489
A25: EBIT | C25: =C20+C23 -> 9649 | D25: =D20+D23 -> 10183 | E25: =E20+E23 -> 8917 | F25: =F20+F23 -> 12712 | G25: =G20+G23 -> 14547.365 | H25: =H20+H23 -> 15200.286
A26: EBIT Margin % | C26: =C25/C6 -> 0.22437448 | D26: =D25/D6 -> 0.22255978 | E26: =E25/E6 -> 0.18947749 | F26: =F25/F6 -> 0.26515926 | G26: =G25/G6 -> 0.28899343 | H26: =H25/H6 -> 0.2875849
A28: Below the Line
A30: Interest Expense (from Debt Schedule) | C30: -882 | D30: -1527 | E30: -1656 | F30: -1654 | G30: =G69 -> -1426.284 | H30: =H69 -> -1246.284
A31: Associates & Other Non-Operating | C31: 1210 | D31: 2261 | E31: 3762 | F31: 3104 | G31: =F31 -> 3104 | H31: =G31 -> 3104
A33: Profit Before Tax (PBT) | C33: =C25+C30+C31 -> 9977 | D33: =D25+D30+D31 -> 10917 | E33: =E25+E30+E31 -> 11023 | F33: =F25+F30+F31 -> 14162 | G33: =G25+G30+G31 -> 16225.082 | H33: =H25+H30+H31 -> 17058.002
A34: Tax Expense | C34: -2115 | D34: -2249 | E34: -2437 | F34: -2861 | G34: =-(G33*Assumptions!B10) -> -3001.6401 | H34: =-(H33*Assumptions!B10) -> -3155.7304
A36: NET PROFIT | C36: =C33+C34 -> 7862 | D36: =D33+D34 -> 8668 | E36: =E33+E34 -> 8586 | F36: =F33+F34 -> 11301 | G36: =G33+G34 -> 13223.441 | H36: =H33+H34 -> 13902.272
A37: Net Profit Margin % | C37: =C36/C6 -> 0.1828202 | D37: =D36/D6 -> 0.18944792 | E37: =E36/E6 -> 0.18244406 | F37: =F36/F6 -> 0.23572725 | G37: =G36/G6 -> 0.26269276 | H37: =H36/H6 -> 0.26302686
A39: Per Share
A41: Shares Outstanding (millions) | C41: 4350 | D41: 4339 | E41: 4320 | F41: 4313 | G41: 4313 | H41: 4313
A42: Earnings Per Share (EPS $) | C42: =C36/C41 -> 1.8073563 | D42: =D36/D41 -> 1.9976953 | E42: =E36/E41 -> 1.9875 | F42: =F36/F41 -> 2.6202179 | G42: =G36/G41 -> 3.0659498 | H42: =H36/H41 -> 3.2233415
A43: Dividend Per Share (DPS $) | C43: 1.76 | D43: 1.84 | E43: 1.94 | F43: 2.04 | G43: =G42*Assumptions!B11 -> 2.2994623 | H43: =H42*Assumptions!B11 -> 2.4175061
A45: Growth Rates
A47: Revenue Growth % | D47: =IFERROR(D6/C6-1,0) -> 0.06394754 | E47: =IFERROR(E6/D6-1,0) -> 0.028565808 | F47: =IFERROR(F6/E6-1,0) -> 0.018699135 | G47: =IFERROR(G6/F6-1,0) -> 0.05 | H47: =IFERROR(H6/G6-1,0) -> 0.05
A48: EBITDA Growth % | D48: =IFERROR(D20/C20-1,0) -> 0.036850307 | E48: =IFERROR(E20/D20-1,0) -> -0.11661215 | F48: =IFERROR(F20/E20-1,0) -> 0.37730184 | G48: =IFERROR(G20/F20-1,0) -> 0.13390463 | H48: =IFERROR(H20/G20-1,0) -> 0.05
A49: Net Profit Growth % | D49: =IFERROR(D36/C36-1,0) -> 0.10251844 | E49: =IFERROR(E36/D36-1,0) -> -0.0094600831 | F49: =IFERROR(F36/E36-1,0) -> 0.31621244 | G49: =IFERROR(G36/F36-1,0) -> 0.17011251 | H49: =IFERROR(H36/G36-1,0) -> 0.051335392
A51: PP&E SCHEDULE
A53: Opening Gross PP&E | C53: 9920 | D53: =C102 -> 9841 | E53: =D102 -> 9236 | F53: =E102 -> 10303 | G53: =F102 -> 9613 | H53: =G58 -> 10770.444
A54: + Capital Expenditure (CapEx) | C54: 1484 | D54: 1852 | E54: 2064 | F54: 2112 | G54: =G6*Assumptions!B13 -> 2214.8742 | H54: =H6*Assumptions!B13 -> 2325.6179
A55: Depreciation for the Year | C55: -1260 | D55: -1128 | E55: -1075 | F55: -1050 | G55: =-(G53*Assumptions!B14) -> -1057.43 | H55: =-(H53*Assumptions!B14) -> -1184.7489
A56: Accumulated Depreciation
A58: Closing PP&E (Net) → feeds BS + IS D&A | C58: =C53+C54+C55 -> 10144 | D58: =D53+D54+D55 -> 10565 | E58: =E53+E54+E55 -> 10225 | F58: =F53+F54+F55 -> 11365 | G58: =G53+G54+G55 -> 10770.444 | H58: =H53+H54+H55 -> 11911.313
A59: CapEx % of Revenue | C59: =C54/C6 -> 0.034508418 | D59: =D54/D6 -> 0.040477335 | E59: =E54/E6 -> 0.043857972 | F59: =F54/F6 -> 0.04405415 | G59: =G54/G6 -> 0.044 | H59: =H54/H6 -> 0.044
...
